Workbook
Name ChronologieNative_Date_de_facturation: #N/A
Name RechercheClients: [1]!ListeClients[Rechercher]
Name Segment_Article: #N/A
Name Segment_Catégorie: #N/A
Name Segment_Client: #N/A

Sheet RECAPITULATIF
A2: Clients | I2: Articles
A4: Clients | B4: Commandés | C4: Payés | D4: Due | I4: Articles | J4: Frais | K4: Gains
A5: Client Ponctuel | B5: 35000 | C5: 20000 | D5: 15000 | I5: Chemise | J5: 7000 | K5: 13000
A6: Client1 | B6: 55000 | C6: 55000 | D6: 0 | I6: Robe | J6: 90500 | K6: 97500
A7: Client4 | B7: 80000 | C7: 45000 | D7: 35000 | I7: Deux pièces | J7: 116000 | K7: 119000
A8: Client5 | B8: 103000 | C8: 103000 | D8: 0 | I8: Couture | J8: 161000 | K8: 12000
A9: Client10 | B9: 140000 | C9: 80000 | D9: 60000 | I9: Trois pièces | J9: 22000 | K9: 38000
A10: Client9 | B10: 24000 | C10: 10000 | D10: 14000 | I10: Tunique | J10: 25000 | K10: 55000
A11: Client12 | B11: 80000 | C11: 80000 | D11: 0 | I11: Total général | J11: 421500 | K11: 334500
A12: Client14 | B12: 45000 | D12: 45000
A13: Client3 | B13: 45000 | C13: 25000 | D13: 20000
A14: Client7 | B14: 17000 | C14: 17000 | D14: 0
A15: Client13 | B15: 132000 | C15: 50000 | D15: 82000
A16: Total général | B16: 756000 | C16: 485000 | D16: 271000
A40: Dépenses | B40: Montant Total | D40: Dépense | E40: Total
A41: 45677 | B41: 12000 | D41: Divers | E41: 28000
A42: Mercerie | B42: 12000 | D42: Electricité | E42: 20000
A43: 45708 | B43: 1750 | D43: Livraison | E43: 5000
A44: Mercerie | B44: 1750 | D44: Mercerie | E44: 45450
A45: 45675 | B45: 1800 | D45: Tontine | E45: 120000
A46: Mercerie | B46: 1800 | D46: Transport | E46: 10000
A47: 45679 | B47: 5000 | D47: Total général | E47: 228450
A48: Transport | B48: 5000
A49: 45713 | B49: 6400
A50: Mercerie | B50: 6400
A51: 45709 | B51: 5600
A52: Mercerie | B52: 5600
A53: 45718 | B53: 4900
A54: Mercerie | B54: 4900
A55: 45720 | B55: 5600
A56: Mercerie | B56: 5600
A57: 45721 | B57: 6400 | F57: Date | G57: Ventes | H57: Bénéfices | I57: Gains perçus
A58: Mercerie | B58: 6400 | F58: 45401 | G58: 80000 | H58: 37000 | I58: 37000
A59: 45403 | B59: 35000 | F59: 45402 | G59: 209000 | H59: 98000 | I59: 84000
A60: Divers | B60: 5000 | F60: 45403 | G60: 60000 | H60: 38000 | I60: -22000
A61: Electricité | B61: 20000 | F61: 45679 | G61: 35000 | H61: 22000 | I61: -13000
A62: Livraison | B62: 5000 | F62: 45680 | G62: 80000 | H62: 55000 | I62: 55000
A63: Transport | B63: 5000 | F63: 45712 | G63: 35000 | H63: 22000 | I63: 7000
A64: 45404 | B64: 144000 | F64: 45713 | G64: 18000 | H64: 13000 | I64: 13000
A65: Divers | B65: 23000 | F65: 45714 | G65: 45000 | H65: 23500 | I65: -21500
...

Sheet Tableau de Bord
A1: Ecart | C1: Dépenses Totales | E1: Ventes Totales | G1: Gains Total | I1: Total Encaissé | K1: Total Gains perçus
A2: =I2-C2 -> 256550 | C2: =GETPIVOTDATA("Montant",RECAPITULATIF!$A$40) -> 228450 | E2: =GETPIVOTDATA("Commandés",RECAPITULATIF!$A$4) -> 756000 | G2: =GETPIVOTDATA("Bénéfices",RECAPITULATIF!$F$57) -> 334500 | I2: =GETPIVOTDATA("Payés",RECAPITULATIF!$A$4) -> 485000 | K2: =GETPIVOTDATA("Gains perçus",RECAPITULATIF!$F$57) -> 63500
C4: Dépenses du jour | E4: Ventes du jour | G4: Gains du Jour | I4: Encaissé | K4: Gains perçus
C5: =SUMIF(FacturesPrincipal9[Date],TODAY(),FacturesPrincipal9[Montant]) -> 0 | E5: =SUMIF(FacturesPrincipal[Date de facturation],TODAY(),FacturesPrincipal[Total à payer]) -> 0 | G5: =SUMIF(FacturesPrincipal[Date de facturation],TODAY(),FacturesPrincipal[Bénéfice]) -> 0 | I5: =SUMIF(FacturesPrincipal[Date de facturation],TODAY(),FacturesPrincipal[Payé]) -> 0 | K5: =SUMIF(FacturesPrincipal[Date de facturation],TODAY(),FacturesPrincipal[Bénéfice perçu]) -> 0

Sheet VENTES
B2: Ventes
B3: N° de facture | C3: Client | D3: Date de facturation | E3: Article | F3: Qté | G3: Prix Unitaire | H3: Total à payer | I3: Payé | J3: Restant | K3: Frais Produit | L3: Bénéfice | M3: Bénéfice perçu | N3: Notes
B4: 000001 | C4: Client1 | D4: 45401 | E4: Robe | F4: 1 | G4: 35000 | H4: =FacturesPrincipal[[#This Row],[Qté]]*FacturesPrincipal[[#This Row],[Prix Unitaire]] -> 35000 | I4: 35000 | J4: =FacturesPrincipal[[#This Row],[Total à payer]]-FacturesPrincipal[[#This Row],[Payé]] -> 0 | K4: 21500 | L4: =FacturesPrincipal[[#This Row],[Total à payer]]-FacturesPrincipal[[#This Row],[Frais Produit]] -> 13500 | M4: =FacturesPrincipal[[#This Row],[Payé]]-FacturesPrincipal[[#This Row],[Frais Produit]] -> 13500 | N4: Robe simple
B5: 000002 | C5: Client4 | D5: 45401 | E5: Robe | F5: 1 | G5: 45000 | H5: =FacturesPrincipal[[#This Row],[Qté]]*FacturesPrincipal[[#This Row],[Prix Unitaire]] -> 45000 | I5: 45000 | J5: =FacturesPrincipal[[#This Row],[Total à payer]]-FacturesPrincipal[[#This Row],[Payé]] -> 0 | K5: 21500 | L5: =FacturesPrincipal[[#This Row],[Total à payer]]-FacturesPrincipal[[#This Row],[Frais Produit]] -> 23500 | M5: =FacturesPrincipal[[#This Row],[Payé]]-FacturesPrincipal[[#This Row],[Frais Produit]] -> 23500 | N5: Robe simple
B6: 000003 | C6: Client5 | D6: 45402 | E6: Deux pièces | F6: 1 | G6: 85000 | H6: =FacturesPrincipal[[#This Row],[Qté]]*FacturesPrincipal[[#This Row],[Prix Unitaire]] -> 85000 | I6: 85000 | J6: =FacturesPrincipal[[#This Row],[Total à payer]]-FacturesPrincipal[[#This Row],[Payé]] -> 0 | K6: 43000 | L6: =FacturesPrincipal[[#This Row],[Total à payer]]-FacturesPrincipal[[#This Row],[Frais Produit]] -> 42000 | M6: =FacturesPrincipal[[#This Row],[Payé]]-FacturesPrincipal[[#This Row],[Frais Produit]] -> 42000 | N6: Deux pièces homme
B7: 000004 | C7: Client10 | D7: 45402 | E7: Deux pièces | F7: 1 | G7: 80000 | H7: =FacturesPrincipal[[#This Row],[Qté]]*FacturesPrincipal[[#This Row],[Prix Unitaire]] -> 80000 | I7: 80000 | J7: =FacturesPrincipal[[#This Row],[Total à payer]]-FacturesPrincipal[[#This Row],[Payé]] -> 0 | K7: 47000 | L7: =FacturesPrincipal[[#This Row],[Total à payer]]-FacturesPrincipal[[#This Row],[Frais Produit]] -> 33000 | M7: =FacturesPrincipal[[#This Row],[Payé]]-FacturesPrincipal[[#This Row],[Frais Produit]] -> 33000 | N7: Deux pièces homme Daminé
B8: 000005 | C8: Client1 | D8: 45402 | E8: Chemise | F8: 1 | G8: 20000 | H8: =FacturesPrincipal[[#This Row],[Qté]]*FacturesPrincipal[[#This Row],[Prix Unitaire]] -> 20000 | I8: 20000 | J8: =FacturesPrincipal[[#This Row],[Total à payer]]-FacturesPrincipal[[#This Row],[Payé]] -> 0 | K8: 7000 | L8: =FacturesPrincipal[[#This Row],[Total à payer]]-FacturesPrincipal[[#This Row],[Frais Produit]] -> 13000 | M8: =FacturesPrincipal[[#This Row],[Payé]]-FacturesPrincipal[[#This Row],[Frais Produit]] -> 13000
B9: 000006 | C9: Client9 | D9: 45402 | E9: Couture | F9: 1 | G9: 24000 | H9: =FacturesPrincipal[[#This Row],[Qté]]*FacturesPrincipal[[#This Row],[Prix Unitaire]] -> 24000 | I9: 10000 | J9: =FacturesPrincipal[[#This Row],[Total à payer]]-FacturesPrincipal[[#This Row],[Payé]] -> 14000 | K9: 14000 | L9: =FacturesPrincipal[[#This Row],[Total à payer]]-FacturesPrincipal[[#This Row],[Frais Produit]] -> 10000 | M9: =FacturesPrincipal[[#This Row],[Payé]]-FacturesPrincipal[[#This Row],[Frais Produit]] -> -4000
B10: 000007 | C10: Client10 | D10: 45403 | E10: Trois pièces | F10: 1 | G10: 60000 | H10: =FacturesPrincipal[[#This Row],[Qté]]*FacturesPrincipal[[#This Row],[Prix Unitaire]] -> 60000 | J10: =FacturesPrincipal[[#This Row],[Total à payer]]-FacturesPrincipal[[#This Row],[Payé]] -> 60000 | K10: 22000 | L10: =FacturesPrincipal[[#This Row],[Total à payer]]-FacturesPrincipal[[#This Row],[Frais Produit]] -> 38000 | M10: =FacturesPrincipal[[#This Row],[Payé]]-FacturesPrincipal[[#This Row],[Frais Produit]] -> -22000
B11: 000008 | C11: Client4 | D11: 45679 | E11: Deux pièces | F11: 1 | G11: 35000 | H11: =FacturesPrincipal[[#This Row],[Qté]]*FacturesPrincipal[[#This Row],[Prix Unitaire]] -> 35000 | J11: =FacturesPrincipal[[#This Row],[Total à payer]]-FacturesPrincipal[[#This Row],[Payé]] -> 35000 | K11: 13000 | L11: =FacturesPrincipal[[#This Row],[Total à payer]]-FacturesPrincipal[[#This Row],[Frais Produit]] -> 22000 | M11: =FacturesPrincipal[[#This Row],[Payé]]-FacturesPrincipal[[#This Row],[Frais Produit]] -> -13000 | N11: Ensemble beige foncé
B12: 000009 | C12: Client12 | D12: 45680 | E12: Tunique | F12: 1 | G12: 80000 | H12: =FacturesPrincipal[[#This Row],[Qté]]*FacturesPrincipal[[#This Row],[Prix Unitaire]] -> 80000 | I12: 80000 | J12: =FacturesPrincipal[[#This Row],[Total à payer]]-FacturesPrincipal[[#This Row],[Payé]] -> 0 | K12: 25000 | L12: =FacturesPrincipal[[#This Row],[Total à payer]]-FacturesPrincipal[[#This Row],[Frais Produit]] -> 55000 | M12: =FacturesPrincipal[[#This Row],[Payé]]-FacturesPrincipal[[#This Row],[Frais Produit]] -> 55000 | N12: Robe dentelle Mauve
B13: 000010 | C13: Client Ponctuel | D13: 45712 | E13: Deux pièces | F13: 1 | G13: 35000 | H13: =FacturesPrincipal[[#This Row],[Qté]]*FacturesPrincipal[[#This Row],[Prix Unitaire]] -> 35000 | I13: 20000 | J13: =FacturesPrincipal[[#This Row],[Total à payer]]-FacturesPrincipal[[#This Row],[Payé]] -> 15000 | K13: 13000 | L13: =FacturesPrincipal[[#This Row],[Total à payer]]-FacturesPrincipal[[#This Row],[Frais Produit]] -> 22000 | M13: =FacturesPrincipal[[#This Row],[Payé]]-FacturesPrincipal[[#This Row],[Frais Produit]] -> 7000 | N13: Deux pièces gris
B14: 000011 | C14: Client5 | D14: 45713 | E14: Robe | F14: 2 | G14: 9000 | H14: =FacturesPrincipal[[#This Row],[Qté]]*FacturesPrincipal[[#This Row],[Prix Unitaire]] -> 18000 | I14: 18000 | J14: =FacturesPrincipal[[#This Row],[Total à payer]]-FacturesPrincipal[[#This Row],[Payé]] -> 0 | K14: 5000 | L14: =FacturesPrincipal[[#This Row],[Total à payer]]-FacturesPrincipal[[#This Row],[Frais Produit]] -> 13000 | M14: =FacturesPrincipal[[#This Row],[Payé]]-FacturesPrincipal[[#This Row],[Frais Produit]] -> 13000
B15: 000012 | C15: Client14 | D15: 45714 | E15: Robe | F15: 1 | G15: 45000 | H15: =FacturesPrincipal[[#This Row],[Qté]]*FacturesPrincipal[[#This Row],[Prix Unitaire]] -> 45000 | J15: =FacturesPrincipal[[#This Row],[Total à payer]]-FacturesPrincipal[[#This Row],[Payé]] -> 45000 | K15: 21500 | L15: =FacturesPrincipal[[#This Row],[Total à payer]]-FacturesPrincipal[[#This Row],[Frais Produit]] -> 23500 | M15: =FacturesPrincipal[[#This Row],[Payé]]-FacturesPrincipal[[#This Row],[Frais Produit]] -> -21500
B16: 000013 | C16: Client3 | D16: 45719 | E16: Robe | F16: 1 | G16: 45000 | H16: =FacturesPrincipal[[#This Row],[Qté]]*FacturesPrincipal[[#This Row],[Prix Unitaire]] -> 45000 | I16: 25000 | J16: =FacturesPrincipal[[#This Row],[Total à payer]]-FacturesPrincipal[[#This Row],[Payé]] -> 20000 | K16: 21000 | L16: =FacturesPrincipal[[#This Row],[Total à payer]]-FacturesPrincipal[[#This Row],[Frais Produit]] -> 24000 | M16: =FacturesPrincipal[[#This Row],[Payé]]-FacturesPrincipal[[#This Row],[Frais Produit]] -> 4000
B17: 000014 | C17: Client7 | D17: 45718 | E17: Couture | F17: 1 | G17: 17000 | H17: =FacturesPrincipal[[#This Row],[Qté]]*FacturesPrincipal[[#This Row],[Prix Unitaire]] -> 17000 | I17: 17000 | J17: =FacturesPrincipal[[#This Row],[Total à payer]]-FacturesPrincipal[[#This Row],[Payé]] -> 0 | K17: 15000 | L17: =FacturesPrincipal[[#This Row],[Total à payer]]-FacturesPrincipal[[#This Row],[Frais Produit]] -> 2000 | M17: =FacturesPrincipal[[#This Row],[Payé]]-FacturesPrincipal[[#This Row],[Frais Produit]] -> 2000
B18: 000015 | C18: Client13 | D18: 45686 | E18: Couture | F18: 1 | G18: 132000 | H18: =FacturesPrincipal[[#This Row],[Qté]]*FacturesPrincipal[[#This Row],[Prix Unitaire]] -> 132000 | I18: 50000 | J18: =FacturesPrincipal[[#This Row],[Total à payer]]-FacturesPrincipal[[#This Row],[Payé]] -> 82000 | K18: 20000 | L18: =FacturesPrincipal[[#This Row],[Total à payer]]-FacturesPrincipal[[#This Row],[Frais Produit]] -> 112000 | M18: =FacturesPrincipal[[#This Row],[Payé]]-FacturesPrincipal[[#This Row],[Frais Produit]] -> 30000
B19: Totaux | C19: ="Total des ventes: "&SUBTOTAL(103,FacturesPrincipal[N° de facture]) -> Total des ventes: 15 | H19: =SUBTOTAL(109,FacturesPrincipal[Total à payer]) -> 756000 | I19: =SUBTOTAL(109,FacturesPrincipal[Payé]) -> 485000 | J19: =SUBTOTAL(109,FacturesPrincipal[Restant]) -> 271000 | K19: =SUBTOTAL(109,FacturesPrincipal[Frais Produit]) -> 309500 | L19: =SUBTOTAL(109,FacturesPrincipal[Bénéfice]) -> 446500 | M19: =SUBTOTAL(109,FacturesPrincipal[Bénéfice perçu]) -> 175500

Sheet DEPENSES
B2: Dépenses
B3: N° | C3: Catégorie | D3: Date | E3: Montant | F3: Notes
B4: 000001 | C4: Mercerie | D4: 45677 | E4: 12000
B5: 000002 | C5: Mercerie | D5: 45708 | E5: 1750
B6: 000003 | C6: Mercerie | D6: 45675 | E6: 1800
B7: 000004 | C7: Transport | D7: 45679 | E7: 5000
B8: 000005 | C8: Shooting | D8: 45713 | E8: 6400
B9: 000006 | C9: Mercerie | D9: 45709 | E9: 5600
B10: 000007 | C10: Mercerie | D10: 45718 | E10: 4900
B11: 000008 | C11: Mercerie | D11: 45720 | E11: 5600
B12: 000009 | C12: Mercerie | D12: 45721 | E12: 6400
B13: 000010 | C13: Electricité | D13: 45403 | E13: 10000
B14: 000011 | C14: Electricité | D14: 45403 | E14: 10000
B15: 000012 | C15: Divers | D15: 45403 | E15: 5000
... B23: 000020 | C23: Divers | D23: 45404 | E23: 2000
B24: Totaux | C24: ="Total des ventes: "&SUBTOTAL(103,FacturesPrincipal9[N°]) -> Total des ventes: 20 | E24: =SUBTOTAL(109,FacturesPrincipal9[Montant]) -> 228450

Sheet DEPENSES FIXES
A1: Libellé | B1: Catégorie | C1: Montant | D1: Fréquence | E1: Montant Mensuel
A2: Depense 1 | B2: Salaire Tailleur | C2: 150000 | D2: Mensuel | E2: =IF(Tableau9[[#This Row],[Fréquence]]="Mensuel",Tableau9[[#This Row],[Montant]],IF(Tableau9[[#This Row],[Fréquence]]="Hebdomadaire",Tableau9[[#This Row],[Montant]]*4,Tableau9[[#This Row],[Montant]]*30)) -> 150000
A3: Depense 2 | B3: Salaire Tailleur | C3: 37500 | D3: Hebdomadaire | E3: =IF(Tableau9[[#This Row],[Fréquence]]="Mensuel",Tableau9[[#This Row],[Montant]],IF(Tableau9[[#This Row],[Fréquence]]="Hebdomadaire",Tableau9[[#This Row],[Montant]]*4,Tableau9[[#This Row],[Montant]]*30)) -> 150000
A4: Depense 3 | B4: Salaire Tailleur | C4: 5000 | D4: Journalier | E4: =IF(Tableau9[[#This Row],[Fréquence]]="Mensuel",Tableau9[[#This Row],[Montant]],IF(Tableau9[[#This Row],[Fréquence]]="Hebdomadaire",Tableau9[[#This Row],[Montant]]*4,Tableau9[[#This Row],[Montant]]*30)) -> 150000
A5: Depense 4 | B5: Salaire Tailleur | C5: 150000 | D5: Mensuel | E5: =IF(Tableau9[[#This Row],[Fréquence]]="Mensuel",Tableau9[[#This Row],[Montant]],IF(Tableau9[[#This Row],[Fréquence]]="Hebdomadaire",Tableau9[[#This Row],[Montant]]*4,Tableau9[[#This Row],[Montant]]*30)) -> 150000
A6: Depense 5 | B6: Salaire Tailleur | C6: 150000 | D6: Mensuel | E6: =IF(Tableau9[[#This Row],[Fréquence]]="Mensuel",Tableau9[[#This Row],[Montant]],IF(Tableau9[[#This Row],[Fréquence]]="Hebdomadaire",Tableau9[[#This Row],[Montant]]*4,Tableau9[[#This Row],[Montant]]*30)) -> 150000
A7: Depense 6 | B7: Loyer | C7: 150000 | D7: Mensuel | E7: =IF(Tableau9[[#This Row],[Fréquence]]="Mensuel",Tableau9[[#This Row],[Montant]],IF(Tableau9[[#This Row],[Fréquence]]="Hebdomadaire",Tableau9[[#This Row],[Montant]]*4,Tableau9[[#This Row],[Montant]]*30)) -> 150000
A8: Depense 7 | B8: Loyer | C8: 50000 | D8: Mensuel | E8: =IF(Tableau9[[#This Row],[Fréquence]]="Mensuel",Tableau9[[#This Row],[Montant]],IF(Tableau9[[#This Row],[Fréquence]]="Hebdomadaire",Tableau9[[#This Row],[Montant]]*4,Tableau9[[#This Row],[Montant]]*30)) -> 50000
A9: Depense 8 | B9: Electricité | C9: 15000 | D9: Mensuel | E9: =IF(Tableau9[[#This Row],[Fréquence]]="Mensuel",Tableau9[[#This Row],[Montant]],IF(Tableau9[[#This Row],[Fréquence]]="Hebdomadaire",Tableau9[[#This Row],[Montant]]*4,Tableau9[[#This Row],[Montant]]*30)) -> 15000
A10: Depense 9 | B10: Electricité | C10: 15000 | D10: Mensuel | E10: =IF(Tableau9[[#This Row],[Fréquence]]="Mensuel",Tableau9[[#This Row],[Montant]],IF(Tableau9[[#This Row],[Fréquence]]="Hebdomadaire",Tableau9[[#This Row],[Montant]]*4,Tableau9[[#This Row],[Montant]]*30)) -> 15000
A11: Depense 10 | B11: Repas | C11: 60000 | D11: Mensuel | E11: =IF(Tableau9[[#This Row],[Fréquence]]="Mensuel",Tableau9[[#This Row],[Montant]],IF(Tableau9[[#This Row],[Fréquence]]="Hebdomadaire",Tableau9[[#This Row],[Montant]]*4,Tableau9[[#This Row],[Montant]]*30)) -> 60000
A12: Depense 11 | B12: Transport | C12: 100000 | D12: Mensuel | E12: =IF(Tableau9[[#This Row],[Fréquence]]="Mensuel",Tableau9[[#This Row],[Montant]],IF(Tableau9[[#This Row],[Fréquence]]="Hebdomadaire",Tableau9[[#This Row],[Montant]]*4,Tableau9[[#This Row],[Montant]]*30)) -> 100000
A13: Depense 12 | B13: Fournitures | C13: 100000 | D13: Mensuel | E13: =IF(Tableau9[[#This Row],[Fréquence]]="Mensuel",Tableau9[[#This Row],[Montant]],IF(Tableau9[[#This Row],[Fréquence]]="Hebdomadaire",Tableau9[[#This Row],[Montant]]*4,Tableau9[[#This Row],[Montant]]*30)) -> 100000
... A18: Depense 17 | B18: Sécurité | C18: 10000 | D18: Mensuel | E18: =IF(Tableau9[[#This Row],[Fréquence]]="Mensuel",Tableau9[[#This Row],[Montant]],IF(Tableau9[[#This Row],[Fréquence]]="Hebdomadaire",Tableau9[[#This Row],[Montant]]*4,Tableau9[[#This Row],[Montant]]*30)) -> 10000
A19: TOTAL | E19: =SUBTOTAL(109,Tableau9[Montant Mensuel]) -> 1507900

Sheet CLIENTS
C2: Clients
B3: Rechercher | C3: Numéro | D3: Nom | E3: Adresse | F3: Téléphone | G3: Mesures
B4: =C4& " - "&#REF! -> #REF! | C4: 1 | D4: Client1 | E4: Yoff
B5: =C5& " - "&#REF! -> #REF! | C5: 2 | D5: Client2
B6: =C6& " - "&#REF! -> #REF! | C6: 3 | D6: Client3
B7: =C7& " - "&#REF! -> #REF! | C7: 4 | D7: Client4
B8: =C8& " - "&#REF! -> #REF! | C8: 5 | D8: Client5
B9: =C9& " - "&#REF! -> #REF! | C9: 6 | D9: Client6
B10: =C10& " - "&#REF! -> #REF! | C10: 7 | D10: Client7
B11: =C11& " - "&#REF! -> #REF! | C11: 8 | D11: Client8
B12: =C12& " - "&#REF! -> #REF! | C12: 9 | D12: Client9
B13: =C13& " - "&#REF! -> #REF! | C13: 10 | D13: Client10
B14: =C14& " - "&#REF! -> #REF! | C14: 11 | D14: Client11
B15: =C15& " - "&#REF! -> #REF! | C15: 12 | D15: Client12
B16: =C16& " - "&#REF! -> #REF! | C16: 13 | D16: Client13
... B18: =C18& " - "&#REF! -> #REF! | C18: 15 | D18: Client Ponctuel
B19: Totaux | C19: ="Total des clients: "&SUBTOTAL(103,ListeClients[[Numéro ]]) -> Total des clients: 15

Sheet ARTICLES
C2: Produits
B3: Rechercher | C3: Numéro | D3: Nom | E3: Prix Standard | F3: Stock | G3: Catégorie
B4: =C4& " - "&#REF! -> #REF! | C4: 2 | D4: Anango | E4: 50000 | F4: 5 | G4: Tenue Femme
B5: =C5& " - "&#REF! -> #REF! | C5: 6 | D5: Chemise | E5: 50000 | F5: 5 | G5: Tenue Homme
B6: =C6& " - "&#REF! -> #REF! | C6: 9 | D6: Couture | E6: 50000
B7: =C7& " - "&#REF! -> #REF! | C7: 7 | D7: Deux pièces | E7: 50000 | F7: 5 | G7: Tenue Homme
B8: =C8& " - "&#REF! -> #REF! | C8: 1 | D8: Grand Boubou | E8: 50000 | F8: 5 | G8: Tenue Femme
B9: =C9& " - "&#REF! -> #REF! | C9: 4 | D9: Robe | E9: 50000 | F9: 5 | G9: Tenue Femme
B10: =C10& " - "&#REF! -> #REF! | C10: 5 | D10: Taille Basse | E10: 50000 | F10: 5 | G10: Tenue Femme
B11: =C11& " - "&#REF! -> #REF! | C11: 8 | D11: Trois pièces | E11: 50000 | F11: 5 | G11: Tenue Homme
B12: =C12& " - "&#REF! -> #REF! | C12: 3 | D12: Tunique | E12: 50000 | F12: 5 | G12: Tenue Femme
B13: Totaux | C13: ="Total des produits: "&SUBTOTAL(103,ListeClients3[[Numéro ]]) -> Total des produits: 9

Sheet CATEGORIE DEPENSES
C2: Catégories Dépenses
B3: Rechercher | C3: Numéro | D3: Libellé
B4: =C4& " - "&#REF! -> #REF! | C4: 1 | D4: Autres Salaires
B5: =C5& " - "&#REF! -> #REF! | C5: 2 | D5: Communication
B6: =C6& " - "&#REF! -> #REF! | C6: 12 | D6: Divers
B7: =C7& " - "&#REF! -> #REF! | C7: 3 | D7: Eau
B8: =C8& " - "&#REF! -> #REF! | C8: 4 | D8: Electricité
B9: =C9& " - "&#REF! -> #REF! | C9: 5 | D9: Informatique et Bureautique
B10: =C10& " - "&#REF! -> #REF! | C10: 13 | D10: Livraison
B11: =C11& " - "&#REF! -> #REF! | C11: 11 | D11: Mercerie
B12: =C12& " - "&#REF! -> #REF! | C12: 6 | D12: Repas
B13: =C13& " - "&#REF! -> #REF! | C13: 7 | D13: Salaire Tailleurs
B14: =C14& " - "&#REF! -> #REF! | C14: 8 | D14: Shooting
B15: =C15& " - "&#REF! -> #REF! | C15: 14 | D15: Tontine
... B17: =C17& " - "&#REF! -> #REF! | C17: 15 | D17: Wifi
B18: Totaux | C18: ="Total des catégories: "&SUBTOTAL(103,ListeClients348[[Numéro ]]) -> Total des catégories: 14

Sheet CATEGORIE PRODUITS
C2: Catégories Produits
B3: Rechercher | C3: Numéro | D3: Libellé
B4: =C4& " - "&#REF! -> #REF! | C4: 1 | D4: Tenue Homme
B5: =C5& " - "&#REF! -> #REF! | C5: 2 | D5: Accessoires
B6: =C6& " - "&#REF! -> #REF! | C6: 3 | D6: Chaussures
B7: =C7& " - "&#REF! -> #REF! | C7: 4 | D7: Tissus
B8: =C8& " - "&#REF! -> #REF! | C8: 5 | D8: Tenue Femme
B9: Totaux | C9: ="Total des catégories: "&SUBTOTAL(103,ListeClients34[[Numéro ]]) -> Total des catégories: 5

Sheet Feuil1

Sheet DETTES
